Traceback (most recent call last):
  File "/usr/lib/python3.4/site-packages/urllib3/connection.py", line 141, in _new_conn
    (self.host, self.port), self.timeout, **extra_kw)
  File "/usr/lib/python3.4/site-packages/urllib3/util/connection.py", line 83, in create_connection
    raise err
  File "/usr/lib/python3.4/site-packages/urllib3/util/connection.py", line 73, in create_connection
    sock.connect(sa)
TimeoutError: [Errno 110] Connection timed out

During handling of the above exception, another exception occurred:

Traceback (most recent call last):
  File "/usr/lib/python3.4/site-packages/urllib3/connectionpool.py", line 601, in urlopen
    chunked=chunked)
  File "/usr/lib/python3.4/site-packages/urllib3/connectionpool.py", line 357, in _make_request
    conn.request(method, url, **httplib_request_kw)
  File "/usr/lib64/python3.4/http/client.py", line 1137, in request
    self._send_request(method, url, body, headers)
  File "/usr/lib64/python3.4/http/client.py", line 1182, in _send_request
    self.endheaders(body)
  File "/usr/lib64/python3.4/http/client.py", line 1133, in endheaders
    self._send_output(message_body)
  File "/usr/lib64/python3.4/http/client.py", line 963, in _send_output
    self.send(msg)
  File "/usr/lib64/python3.4/http/client.py", line 898, in send
    self.connect()
  File "/usr/lib/python3.4/site-packages/urllib3/connection.py", line 166, in connect
    conn = self._new_conn()
  File "/usr/lib/python3.4/site-packages/urllib3/connection.py", line 150, in _new_conn
    self, "Failed to establish a new connection: %s" % e)
urllib3.exceptions.NewConnectionError: : Failed to establish a new connection: [Errno 110] Connection timed out

During handling of the above exception, another exception occurred:

Traceback (most recent call last):
  File "/usr/lib/python3.4/site-packages/requests/adapters.py", line 440, in send
    timeout=timeout
  File "/usr/lib/python3.4/site-packages/urllib3/connectionpool.py", line 639, in urlopen
    _stacktrace=sys.exc_info()[2])
  File "/usr/lib/python3.4/site-packages/urllib3/util/retry.py", line 388, in increment
    raise MaxRetryError(_pool, url, error or ResponseError(cause))
urllib3.exceptions.MaxRetryError: HTTPConnectionPool(host='xxxxxx', port=8086): Max retries exceeded with url: /write?db=test (Caused by NewConnectionError(': Failed to establish a new connection: [Errno 110] Connection timed out',))

During handling of the above exception, another exception occurred:

Traceback (most recent call last):
  File "/shree/shree.py", line 76, in 
    send_influx(get_times(get_args(variables)))
  File "/shree/shree.py", line 70, in send_influx
    "statusCode":   jsn["statusCode"],
  File "/usr/lib/python3.4/site-packages/influxdb/client.py", line 468, in write_points
    tags=tags, protocol=protocol)
  File "/usr/lib/python3.4/site-packages/influxdb/client.py", line 532, in _write_points
    protocol=protocol
  File "/usr/lib/python3.4/site-packages/influxdb/client.py", line 312, in write
    headers=headers
  File "/usr/lib/python3.4/site-packages/influxdb/client.py", line 252, in request
    timeout=self._timeout
  File "/usr/lib/python3.4/site-packages/requests/sessions.py", line 508, in request
    resp = self.send(prep, **send_kwargs)
  File "/usr/lib/python3.4/site-packages/requests/sessions.py", line 618, in send
    r = adapter.send(request, **kwargs)
  File "/usr/lib/python3.4/site-packages/requests/adapters.py", line 508, in send
    raise ConnectionError(e, request=request)
requests.exceptions.ConnectionError: HTTPConnectionPool(host='xxxxxxxx', port=8086): Max retries exceeded with url: /write?db=test (Caused by NewConnectionError(': Failed to establish a new connection: [Errno 110] Connection timed out',))
